<robot name="onshape">
  <link name="10_dof_base_link">
    <visual>
      <origin xyz="-8.8525663098116408704e-08 5.7660782994858024247e-05 1.807164633216126136e-09" rpy="6.8888110274651766193e-11 -5.0144680395298187004e-08 7.1773723064297561815e-11" />
      <geometry>
        <mesh filename="../meshes/torso.stl"/>
      </geometry>
      <material name="10_dof_base_link_material">
        <color rgba="0.79215686274509800047 0.81960784313725487671 0.93333333333333334814 1.0"/>
      </material>
    </visual>
    <collision>
      <origin xyz="-8.8525663098116408704e-08 5.7660782994858024247e-05 1.807164633216126136e-09" rpy="6.8888110274651766193e-11 -5.0144680395298187004e-08 7.1773723064297561815e-11" />
      <geometry>
        <!-- <mesh filename="../meshes/10_dof_base_link.stl"/> -->
        <box size="0.2 0.1 0.1"/>
      </geometry>
    </collision>
    <inertial>
      <origin xyz="-0.010021271649920398747 1.3557795833418114572e-05 -0.014236482071857426215" rpy="0 0 0"/>
      <mass value="1.2245306366669659326" />
      <inertia ixx="0.008810708408077192258" ixy="-3.2525573047210394603e-06" ixz="-0.00014960007807148680676" iyy="0.00099529401098946874982" iyz="1.9907576807785989006e-06" izz="0.0092350517607848736645" />
    </inertial>
  </link>

  <link name="left_hip_yaw_assembled_link">
    <visual>
      <origin xyz="1.7347234759768070944e-18 1.3877787807814456755e-17 0" rpy="-3.141592653589793116 -2.657632046459371556e-19 5.0919519512311372959e-19" />
      <geometry>
        <mesh filename="../meshes/left_hip_yaw_assembled_link.stl"/>
      </geometry>
      <material name="left_hip_yaw_assembled_link_material">
        <color rgba="0.62745098039215685404 0.62745098039215685404 0.62745098039215685404 1.0"/>
      </material>
    </visual>
    <collision>
      <origin xyz="1.7347234759768070944e-18 1.3877787807814456755e-17 0" rpy="-3.141592653589793116 -2.657632046459371556e-19 5.0919519512311372959e-19" />
      <geometry>
        <mesh filename="../meshes/left_hip_yaw_assembled_link.stl"/>
      </geometry>
    </collision>
    <inertial>
      <origin xyz="-0.038199108326162294069 -0.00055603061731508143187 0.049872228042224381328" rpy="0 0 0"/>
      <mass value="0.23040104617725787328" />
      <inertia ixx="0.00022816101113524791546" ixy="-1.4049915467919655682e-06" ixz="2.5273654035002815721e-05" iyy="0.00019338791885756636581" iyz="7.2103711609809702675e-07" izz="0.00013157871443094466737" />
    </inertial>
  </link>

  <link name="left_hip_roll_assembled_link">
    <visual>
      <origin xyz="0 2.7755575615628913511e-17 0" rpy="-3.141592653589793116 -8.6740594182115469816e-19 -2.5845942875821775783e-26" />
      <geometry>
        <mesh filename="../meshes/left_hip_roll_assembled_link.stl"/>
      </geometry>
      <material name="left_hip_roll_assembled_link_material">
        <color rgba="0.62745098039215685404 0.62745098039215685404 0.62745098039215685404 1.0"/>
      </material>
    </visual>
    <collision>
      <origin xyz="0 2.7755575615628913511e-17 0" rpy="-3.141592653589793116 -8.6740594182115469816e-19 -2.5845942875821775783e-26" />
      <geometry>
        <mesh filename="../meshes/left_hip_roll_assembled_link.stl"/>
      </geometry>
    </collision>
    <inertial>
      <origin xyz="-0.038199108326162280191 -0.00055603061731506755409 0.049872228042224388267" rpy="0 0 0"/>
      <mass value="0.23040104617725792879" />
      <inertia ixx="0.00022816101113524791546" ixy="-1.4049915467919685328e-06" ixz="2.5273654035002812333e-05" iyy="0.00019338791885756644712" iyz="7.2103711609809734438e-07" izz="0.00013157871443094474868" />
    </inertial>
  </link>

  <link name="left_thigh_link">
    <visual>
      <origin xyz="-6.9388939039072283776e-18 -4.1633363423443370266e-17 2.6367796834847467835e-16" rpy="-6.7762635780344027125e-21 -9.4303337708416838275e-19 -6.6174449004242228683e-24" />
      <geometry>
        <mesh filename="../meshes/left_thigh_link.stl"/>
      </geometry>
      <material name="left_thigh_link_material">
        <color rgba="0.62745098039215685404 0.62745098039215685404 0.62745098039215685404 1.0"/>
      </material>
    </visual>
    <collision>
      <origin xyz="-6.9388939039072283776e-18 -4.1633363423443370266e-17 2.6367796834847467835e-16" rpy="-6.7762635780344027125e-21 -9.4303337708416838275e-19 -6.6174449004242228683e-24" />
      <geometry>
        <mesh filename="../meshes/left_thigh_link.stl"/>
      </geometry>
    </collision>
    <inertial>
      <origin xyz="-0.0012895905818432005369 0.12460710594886220681 -0.010238876555824992856" rpy="0 0 0"/>
      <mass value="0.24065665756599849412" />
      <inertia ixx="0.001550796243676469963" ixy="1.0910841204464645607e-05" ixz="1.2225763145551583664e-07" iyy="0.00010254674236237944489" iyz="-6.982240314670675771e-06" izz="0.0016430244598550267608" />
    </inertial>
  </link>

  <link name="left_knee_motor">
    <visual>
      <origin xyz="3.2816069428336092084e-06 -0.03399999984163321054 0.0030000000000006410428" rpy="3.141592653589793116 5.0951362877729409943e-19 6.6174449004242228683e-24" />
      <geometry>
        <mesh filename="../meshes/left_knee_motor.stl"/>
      </geometry>
      <material name="left_knee_motor_material">
        <color rgba="0.79215686274509800047 0.81960784313725487671 0.93333333333333334814 1.0"/>
      </material>
    </visual>
    <collision>
      <origin xyz="3.2816069428336092084e-06 -0.03399999984163321054 0.0030000000000006410428" rpy="3.141592653589793116 5.0951362877729409943e-19 6.6174449004242228683e-24" />
      <geometry>
        <mesh filename="../meshes/left_knee_motor.stl"/>
      </geometry>
    </collision>
    <inertial>
      <origin xyz="6.7940288189654232253e-05 -0.034052612870053913796 -0.015287354009826472495" rpy="0 0 0"/>
      <mass value="0.43770819121562731802" />
      <inertia ixx="0.00020963913868648432408" ixy="2.4636800277929715866e-07" ixz="-4.220689812428420725e-08" iyy="0.00021022742338103672308" iyz="-6.1686959826845027281e-07" izz="0.00033700522316780609673" />
    </inertial>
  </link>

  <link name="left_shin_motor_down_link">
    <visual>
      <origin xyz="-1.3877787807814456755e-17 0 -9.5756735873919751612e-16" rpy="3.141592653589793116 7.4076360289060405625e-19 -5.9453606527248864131e-24" />
      <geometry>
        <mesh filename="../meshes/left_shin_motor_down_link.stl"/>
      </geometry>
      <material name="left_shin_motor_down_link_material">
        <color rgba="0.62745098039215685404 0.62745098039215685404 0.62745098039215685404 1.0"/>
      </material>
    </visual>
    <collision>
      <origin xyz="-1.3877787807814456755e-17 0 -9.5756735873919751612e-16" rpy="3.141592653589793116 7.4076360289060405625e-19 -5.9453606527248864131e-24" />
      <geometry>
        <mesh filename="../meshes/left_shin_motor_down_link.stl"/>
      </geometry>
    </collision>
    <inertial>
      <origin xyz="-0.0012895905818432076926 -0.1246071059488622762 0.010238876555824297232" rpy="0 0 0"/>
      <mass value="0.24065665756599849412" />
      <inertia ixx="0.0015507962436764708303" ixy="-1.0910841204464647301e-05" ixz="-1.222576314555151749e-07" iyy="0.00010254674236237948555" iyz="-6.9822403146706766181e-06" izz="0.0016430244598550269777" />
    </inertial>
  </link>

  <link name="left_ankle_motor">
    <visual>
      <origin xyz="3.2816069427121785651e-06 -0.033999999841633266051 0.0030000000000003912426" rpy="3.141592653589793116 -5.6027982980336038162e-19 -3.0760779029315716659e-24" />
      <geometry>
        <mesh filename="../meshes/left_ankle_motor.stl"/>
      </geometry>
      <material name="left_ankle_motor_material">
        <color rgba="0.79215686274509800047 0.81960784313725487671 0.93333333333333334814 1.0"/>
      </material>
    </visual>
    <collision>
      <origin xyz="3.2816069427121785651e-06 -0.033999999841633266051 0.0030000000000003912426" rpy="3.141592653589793116 -5.6027982980336038162e-19 -3.0760779029315716659e-24" />
      <geometry>
        <mesh filename="../meshes/left_ankle_motor.stl"/>
      </geometry>
    </collision>
    <inertial>
      <origin xyz="6.7940288189625243397e-05 -0.034052612870053206029 -0.015287354009826455148" rpy="0 0 0"/>
      <mass value="0.4377081912156142729" />
      <inertia ixx="0.0002096391386864774665" ixy="2.4636800278043557094e-07" ixz="-4.2206898125546934851e-08" iyy="0.00021022742338103016365" iyz="-6.1686959826829833627e-07" izz="0.00033700522316779726048" />
    </inertial>
  </link>

  <link name="left_foot_10_dof_link">
    <visual>
      <origin xyz="-3.4694469519536141888e-18 0 0.010000000000000244804" rpy="0 1.2659848861477011308e-19 -2.4298430493745187949e-24" />
      <geometry>
        <mesh filename="../meshes/left_foot_10_dof_link.stl"/>
      </geometry>
      <material name="left_foot_10_dof_link_material">
        <color rgba="0.62745098039215685404 0.62745098039215685404 0.62745098039215685404 1.0"/>
      </material>
    </visual>
    <collision>
      <origin xyz="-3.4694469519536141888e-18 0 0.010000000000000244804" rpy="0 1.2659848861477011308e-19 -2.4298430493745187949e-24" />
      <geometry>
        <mesh filename="../meshes/left_foot_10_dof_link.stl"/>
      </geometry>
    </collision>
    <inertial>
      <origin xyz="0.012214117649317153894 0.041306009675621445376 0.0049882604867300525328" rpy="0 0 0"/>
      <mass value="0.17789809743893272853" />
      <inertia ixx="0.00012889817621767815647" ixy="-2.247132736476478441e-05" ixz="-9.956021422815730044e-06" iyy="0.00026369129105520086208" iyz="-2.3093649276737399654e-05" izz="0.00027539564761342323054" />
    </inertial>
  </link>

  <joint name="left_ankle_joint" type="revolute">
    <origin xyz="3.2816069426878924364e-06 -0.033999999841633266051 0.0040000000000006558087" rpy="3.1415926535897900074 -2.7014812817776049377e-17 1.6276071021687969344e-21" />
    <parent link="left_ankle_motor" />
    <child link="left_foot_10_dof_link" />
    <axis xyz="0 0 1"/>
    <limit effort="8" velocity="12" lower="-0.69813170079773179122" upper="0.69813170079773179122"/>
    <joint_properties friction="0.0"/>
  </joint>

  <joint name="left_ankle_motor_to_shin" type="fixed">
    <origin xyz="8.2040104280228787204e-05 -0.23294457981559668625 0.0015469999999988409689" rpy="6.2242860876268239146e-15 -2.5280088545069896347e-17 2.6624875966549861968e-24" />
    <parent link="left_shin_motor_down_link" />
    <child link="left_ankle_motor" />
    <axis xyz="0 0 1"/>
    <limit effort="8" velocity="12" />
    <joint_properties friction="0.0"/>
  </joint>

  <joint name="left_knee_joint" type="revolute">
    <origin xyz="3.2816069428370786554e-06 -0.033999999841633321562 0.0040000000000005586642" rpy="-4.8921743121386886771e-15 -7.4991735506070378833e-18 -5.0069228532984672229e-08" />
    <parent link="left_knee_motor" />
    <child link="left_shin_motor_down_link" />
    <axis xyz="0 0 1"/>
    <limit effort="8" velocity="12" lower="-0.69813170079773179122" upper="-0"/>
    <joint_properties friction="0.0"/>
  </joint>

  <joint name="left_knee_motor_to_thigh" type="fixed">
    <origin xyz="8.2040104280235726097e-05 0.23294457981559649196 -0.0015469999999995209805" rpy="-3.1415926535897900074 2.4644137901954597791e-17 -6.6174449004242228683e-24" />
    <parent link="left_thigh_link" />
    <child link="left_knee_motor" />
    <axis xyz="0 0 1"/>
    <limit effort="8" velocity="12" />
    <joint_properties friction="0.0"/>
  </joint>

  <joint name="left_hip_pitch_joint" type="revolute">
    <origin xyz="-0.020714482720959687123 1.219521932285805299e-06 0.056302758297119850917" rpy="1.8014407889166545292e-05 -1.5707963265881343951 0" />
    <parent link="left_hip_roll_assembled_link" />
    <child link="left_thigh_link" />
    <axis xyz="0 0 1"/>
    <limit effort="8" velocity="12" lower="-1.570796326794896558" upper="0.34906585039886589561"/>
    <joint_properties friction="0.0"/>
  </joint>

  <joint name="left_hip_roll_joint" type="revolute">
    <origin xyz="-0.020714482720959506712 1.2195219322996830869e-06 0.056302758297119871733" rpy="1.5707963267949003328 -6.9790457465458354129e-11 1.5708143412027857355" />
    <parent link="left_hip_yaw_assembled_link" />
    <child link="left_hip_roll_assembled_link" />
    <axis xyz="0 0 1"/>
    <limit effort="8" velocity="12" lower="-0.34906585039886589561" upper="0.34906585039886589561"/>
    <joint_properties friction="0.0"/>
  </joint>

  <joint name="left_hip_yaw_joint" type="revolute">
    <origin xyz="-0.015448260799158839915 0.090058795475540923126 -0.040999998961279135457" rpy="3.1415926535190985547 -5.0144678432644649869e-08 0.0027836016256884551709" />
    <parent link="10_dof_base_link" />
    <child link="left_hip_yaw_assembled_link" />
    <axis xyz="0 0 1"/>
    <limit effort="8" velocity="12" lower="-0.34906585039886589561" upper="0.34906585039886589561"/>
    <joint_properties friction="0.0"/>
  </joint>

  <link name="right_hip_yaw_assembled_link">
    <visual>
      <origin xyz="1.561251128379126385e-17 -2.7755575615628913511e-17 0" rpy="-3.141592653589793116 -2.0781423965292224881e-19 0" />
      <geometry>
        <mesh filename="../meshes/right_hip_yaw_assembled_link.stl"/>
      </geometry>
      <material name="right_hip_yaw_assembled_link_material">
        <color rgba="0.62745098039215685404 0.62745098039215685404 0.62745098039215685404 1.0"/>
      </material>
    </visual>
    <collision>
      <origin xyz="1.561251128379126385e-17 -2.7755575615628913511e-17 0" rpy="-3.141592653589793116 -2.0781423965292224881e-19 0" />
      <geometry>
        <mesh filename="../meshes/right_hip_yaw_assembled_link.stl"/>
      </geometry>
    </collision>
    <inertial>
      <origin xyz="0.038199490336614690122 -0.00055715423494521532696 0.04996983139115786926" rpy="0 0 0"/>
      <mass value="0.23039505974855084558" />
      <inertia ixx="0.00022843409513369377132" ixy="1.4072345445401020898e-06" ixz="-2.5275932885063436283e-05" iyy="0.00019366265860681734778" iyz="9.1501885576562336604e-07" izz="0.00013157493621344400658" />
    </inertial>
  </link>

  <link name="right_hip_roll_assembled_link">
    <visual>
      <origin xyz="1.3877787807814456755e-17 -4.1633363423443370266e-17 0" rpy="-3.141592653589793116 -2.05420640298130488e-19 -1.292469707114105455e-26" />
      <geometry>
        <mesh filename="../meshes/right_hip_roll_assembled_link.stl"/>
      </geometry>
      <material name="right_hip_roll_assembled_link_material">
        <color rgba="0.62745098039215685404 0.62745098039215685404 0.62745098039215685404 1.0"/>
      </material>
    </visual>
    <collision>
      <origin xyz="1.3877787807814456755e-17 -4.1633363423443370266e-17 0" rpy="-3.141592653589793116 -2.05420640298130488e-19 -1.292469707114105455e-26" />
      <geometry>
        <mesh filename="../meshes/right_hip_roll_assembled_link.stl"/>
      </geometry>
    </collision>
    <inertial>
      <origin xyz="0.038199490336614690122 -0.00055715423494522942158 0.049969831391157862321" rpy="0 0 0"/>
      <mass value="0.23039505974855084558" />
      <inertia ixx="0.00022843409513369387974" ixy="1.4072345445401003957e-06" ixz="-2.5275932885063415954e-05" iyy="0.00019366265860681729357" iyz="9.1501885576562326016e-07" izz="0.00013157493621344387106" />
    </inertial>
  </link>

  <link name="right_thigh_link">
    <visual>
      <origin xyz="3.4694469519536141888e-18 1.3877787807814456755e-17 2.0816681711721685133e-16" rpy="0 1.5099282826161956392e-19 -6.617444900424221399e-24" />
      <geometry>
        <mesh filename="../meshes/right_thigh_link.stl"/>
      </geometry>
      <material name="right_thigh_link_material">
        <color rgba="0.62745098039215685404 0.62745098039215685404 0.62745098039215685404 1.0"/>
      </material>
    </visual>
    <collision>
      <origin xyz="3.4694469519536141888e-18 1.3877787807814456755e-17 2.0816681711721685133e-16" rpy="0 1.5099282826161956392e-19 -6.617444900424221399e-24" />
      <geometry>
        <mesh filename="../meshes/right_thigh_link.stl"/>
      </geometry>
    </collision>
    <inertial>
      <origin xyz="0.001313645536442623182 -0.12460737390127793467 -0.010238901919990731071" rpy="0 0 0"/>
      <mass value="0.24065546894893422025" />
      <inertia ixx="0.0015507790479275009032" ixy="1.1190495954178727536e-05" ixz="-1.2360736711995493742e-07" iyy="0.00010255057505729148432" iyz="6.9827460575687484969e-06" izz="0.0016430111185122503546" />
    </inertial>
  </link>

  <link name="right_knee_motor">
    <visual>
      <origin xyz="-3.281606941782366782e-06 -0.033999999841633099518 0.0029999999999996973532" rpy="3.141592653589793116 -4.5226031904436514136e-19 0" />
      <geometry>
        <mesh filename="../meshes/right_knee_motor.stl"/>
      </geometry>
      <material name="right_knee_motor_material">
        <color rgba="0.79215686274509800047 0.81960784313725487671 0.93333333333333334814 1.0"/>
      </material>
    </visual>
    <collision>
      <origin xyz="-3.281606941782366782e-06 -0.033999999841633099518 0.0029999999999996973532" rpy="3.141592653589793116 -4.5226031904436514136e-19 0" />
      <geometry>
        <mesh filename="../meshes/right_knee_motor.stl"/>
      </geometry>
    </collision>
    <inertial>
      <origin xyz="6.1366916907383374578e-05 -0.034052625350507265134 -0.015287354009827412715" rpy="0 0 0"/>
      <mass value="0.43770819121563186993" />
      <inertia ixx="0.00020963923382404599824" ixy="2.4648154436549102092e-07" ixz="-4.2325975194358730788e-08" iyy="0.00021022732824347732574" iyz="-6.1686143933646325626e-07" izz="0.00033700522316781081301" />
    </inertial>
  </link>

  <link name="right_shin_motor_down_link">
    <visual>
      <origin xyz="6.9388939039072283776e-18 5.5511151231257827021e-17 -1.9428902930940239457e-16" rpy="3.141592653589793116 -1.487123073677079856e-19 -6.6174449004242199296e-24" />
      <geometry>
        <mesh filename="../meshes/right_shin_motor_down_link.stl"/>
      </geometry>
      <material name="right_shin_motor_down_link_material">
        <color rgba="0.62745098039215685404 0.62745098039215685404 0.62745098039215685404 1.0"/>
      </material>
    </visual>
    <collision>
      <origin xyz="6.9388939039072283776e-18 5.5511151231257827021e-17 -1.9428902930940239457e-16" rpy="3.141592653589793116 -1.487123073677079856e-19 -6.6174449004242199296e-24" />
      <geometry>
        <mesh filename="../meshes/right_shin_motor_down_link.stl"/>
      </geometry>
    </collision>
    <inertial>
      <origin xyz="0.0013136455364426266514 0.12460737390127800406 0.010238901919990746683" rpy="0 0 0"/>
      <mass value="0.24065546894893422025" />
      <inertia ixx="0.0015507790479275017706" ixy="-1.1190495954178730924e-05" ixz="1.2360736711995469919e-07" iyy="0.00010255057505729148432" iyz="6.9827460575687442618e-06" izz="0.0016430111185122507882" />
    </inertial>
  </link>

  <link name="right_ankle_motor">
    <visual>
      <origin xyz="3.2816069427121785651e-06 -0.033999999841633155029 0.0030000000000004051204" rpy="3.141592653589793116 -1.4927001895154090008e-19 -6.617444900424221399e-24" />
      <geometry>
        <mesh filename="../meshes/right_ankle_motor.stl"/>
      </geometry>
      <material name="right_ankle_motor_material">
        <color rgba="0.79215686274509800047 0.81960784313725487671 0.93333333333333334814 1.0"/>
      </material>
    </visual>
    <collision>
      <origin xyz="3.2816069427121785651e-06 -0.033999999841633155029 0.0030000000000004051204" rpy="3.141592653589793116 -1.4927001895154090008e-19 -6.617444900424221399e-24" />
      <geometry>
        <mesh filename="../meshes/right_ankle_motor.stl"/>
      </geometry>
    </collision>
    <inertial>
      <origin xyz="6.7940288189625243397e-05 -0.034052612870053095007 -0.01528735400982644474" rpy="0 0 0"/>
      <mass value="0.4377081912156142729" />
      <inertia ixx="0.00020963913868647735808" ixy="2.4636800278043530624e-07" ixz="-4.2206898125546306194e-08" iyy="0.00021022742338103016365" iyz="-6.1686959826829886567e-07" izz="0.00033700522316779726048" />
    </inertial>
  </link>

  <link name="right_foot_10_dof_link">
    <visual>
      <origin xyz="-6.9388939039072283776e-18 1.1102230246251565404e-16 0.010000000000000036637" rpy="3.141592653589793116 -1.495087247778510208e-19 0" />
      <geometry>
        <mesh filename="../meshes/right_foot_10_dof_link.stl"/>
      </geometry>
      <material name="right_foot_10_dof_link_material">
        <color rgba="0.62745098039215685404 0.62745098039215685404 0.62745098039215685404 1.0"/>
      </material>
    </visual>
    <collision>
      <origin xyz="-6.9388939039072283776e-18 1.1102230246251565404e-16 0.010000000000000036637" rpy="3.141592653589793116 -1.495087247778510208e-19 0" />
      <geometry>
        <mesh filename="../meshes/right_foot_10_dof_link.stl"/>
      </geometry>
    </collision>
    <inertial>
      <origin xyz="0.012213961577856402227 -0.041306031088184202993 0.0049882268129159811759" rpy="0 0 0"/>
      <mass value="0.1778975924553742316" />
      <inertia ixx="0.0001288981356217085367" ixy="2.247134062600971048e-05" ixz="-9.9557501157508032565e-06" iyy="0.00026368875186821762874" iyz="2.309354256221622133e-05" izz="0.00027539303089120536257" />
    </inertial>
  </link>

  <joint name="right_ankle_joint" type="revolute">
    <origin xyz="3.2816069426878924364e-06 -0.033999999841633155029 0.0040000000000004060086" rpy="-3.1415926535897900074 2.1720554068008287129e-18 -3.141592653589793116" />
    <parent link="right_ankle_motor" />
    <child link="right_foot_10_dof_link" />
    <axis xyz="0 0 1"/>
    <limit effort="8" velocity="12" lower="-0.69813170079773179122" upper="0.69813170079773179122"/>
    <joint_properties friction="0.0"/>
  </joint>

  <joint name="right_ankle_motor_to_shin" type="fixed">
    <origin xyz="-3.7073482355147457934e-05 0.23294459131218325787 0.0015469999999983968797" rpy="3.4553794287655741425e-15 -1.8631702197740713788e-17 3.141592653589793116" />
    <parent link="right_shin_motor_down_link" />
    <child link="right_ankle_motor" />
    <axis xyz="0 0 1"/>
    <limit effort="8" velocity="12" />
    <joint_properties friction="0.0"/>
  </joint>

  <joint name="right_knee_joint" type="revolute">
    <origin xyz="-3.2816069417858362289e-06 -0.033999999841633099518 0.0039999999999996982414" rpy="3.4474478122475132731e-15 6.7955268797642522473e-20 -3.1415925533000530478" />
    <parent link="right_knee_motor" />
    <child link="right_shin_motor_down_link" />
    <axis xyz="0 0 1"/>
    <limit effort="8" velocity="12" lower="-0" upper="0.69813170079773179122"/>
    <joint_properties friction="0.0"/>
  </joint>

  <joint name="right_knee_motor_to_thigh" type="fixed">
    <origin xyz="-3.7073482355150927381e-05 -0.2329445913121831746 -0.0015469999999983968797" rpy="-3.1415926535897900074 2.1655023358986328438e-17 3.141592653589793116" />
    <parent link="right_thigh_link" />
    <child link="right_knee_motor" />
    <axis xyz="0 0 1"/>
    <limit effort="8" velocity="12" />
    <joint_properties friction="0.0"/>
  </joint>

  <joint name="right_hip_pitch_joint" type="revolute">
    <origin xyz="0.020714482720954302541 -1.219252338369170019e-06 0.056297241554987505208" rpy="-3.1415746391817331862 -1.5707963267916837946 0" />
    <parent link="right_hip_roll_assembled_link" />
    <child link="right_thigh_link" />
    <axis xyz="0 0 1"/>
    <limit effort="8" velocity="12" lower="-0.34906585039886589561" upper="1.570796326794896558"/>
    <joint_properties friction="0.0"/>
  </joint>

  <joint name="right_hip_roll_joint" type="revolute">
    <origin xyz="0.02071448272095430948 -1.219252338369170019e-06 0.056297241554987512147" rpy="1.57079632679489678 3.2127874593201277269e-12 -1.5707783123868368502" />
    <parent link="right_hip_yaw_assembled_link" />
    <child link="right_hip_roll_assembled_link" />
    <axis xyz="0 0 1"/>
    <limit effort="8" velocity="12" lower="-0.34906585039886589561" upper="0.34906585039886589561"/>
    <joint_properties friction="0.0"/>
  </joint>

  <joint name="right_hip_yaw_joint" type="revolute">
    <origin xyz="-0.015446141460225827971 -0.089944678857579563047 -0.040999998973574099115" rpy="3.1415926535209051096 5.0144680946418486686e-08 3.141592653589793116" />
    <parent link="10_dof_base_link" />
    <child link="right_hip_yaw_assembled_link" />
    <axis xyz="0 0 1"/>
    <limit effort="8" velocity="12" lower="-0.34906585039886589561" upper="0.34906585039886589561"/>
    <joint_properties friction="0.0"/>
  </joint>

  <link name="additional_weight">
    <visual>
      <origin xyz="-6.9388939039072283776e-18 -2.710505431213761085e-20 -0.050000000000000155431" rpy="3.141592653589793116 -6.617444900424221399e-24 4.6298612454110616434e-27" />
      <geometry>
        <mesh filename="../meshes/additional_weight.stl"/>
      </geometry>
      <material name="additional_weight_material">
        <color rgba="0.64705882352941179736 0.64705882352941179736 0.64705882352941179736 1.0"/>
      </material>
    </visual>
    <collision>
      <origin xyz="-6.9388939039072283776e-18 -2.710505431213761085e-20 -0.050000000000000155431" rpy="3.141592653589793116 -6.617444900424221399e-24 4.6298612454110616434e-27" />
      <geometry>
        <mesh filename="../meshes/additional_weight.stl"/>
      </geometry>
    </collision>
    <inertial>
      <origin xyz="-5.7190546223683737574e-18 -2.7105054635254988277e-20 -0.024999999999999911182" rpy="0 0 0"/>
      <mass value="0.79579314812178392202" />
      <inertia ixx="0.00029130794056903707876" ixy="2.6974342796897762415e-30" ixz="1.9277142457716565769e-27" iyy="0.00029130794056903707876" iyz="-3.2445565347273038397e-30" izz="0.00025103540275399723785" />
    </inertial>
  </link>

  <joint name="weight_to_base" type="fixed">
    <origin xyz="0.031893040747171287619 6.4241565289009446731e-05 0.70300000340643686858" rpy="-3.1415926535209051096 -5.0144680395463669448e-08 7.1773723064297755686e-11" />
    <parent link="10_dof_base_link" />
    <child link="additional_weight" />
    <axis xyz="0 0 1"/>
    <limit effort="8" velocity="12" />
    <joint_properties friction="0.0"/>
  </joint>


</robot>
